Workbook

Sheet Сводка
A1: Сводка по сторис: «Откуда вы о нас узнали?»
A2: Период: 01.05.2026 — 07.05.2026 · Таргетинг: Москва, Санкт-Петербург, Краснодар · Все категории
A4: Воронка
A5: Этап | B5: Кол-во | C5: % от показа | D5: % от увидевших
A6: 1. В таргете (показано) | B6: 60 | C6: 1
A7: 2. Увидели сторис | B7: 50 | C7: 0.83333333 | D7: 1
A8: 3. Прошли опрос | B8: 10 | C8: 0.16666667 | D8: 0.2
A9: 4. Увидели, но не ответили | B9: 40 | C9: 0.66666667 | D9: 0.8
A11: Распределение ответов
A12: Вариант | B12: Голосов | C12: Доля
A13: Через друзей и знакомых | B13: =COUNTIF('Все исполнители'!K:K,A13) -> 2 | C13: =B13/SUM($B$13:$B$17) -> 0.2
A14: Реклама ВКонтакте | B14: =COUNTIF('Все исполнители'!K:K,A14) -> 2 | C14: =B14/SUM($B$13:$B$17) -> 0.2
A15: Поиск в интернете | B15: =COUNTIF('Все исполнители'!K:K,A15) -> 0 | C15: =B15/SUM($B$13:$B$17) -> 0
A16: Telegram-каналы | B16: =COUNTIF('Все исполнители'!K:K,A16) -> 2 | C16: =B16/SUM($B$13:$B$17) -> 0.2
A17: Другое | B17: =COUNTIF('Все исполнители'!K:K,A17) -> 4 | C17: =B17/SUM($B$13:$B$17) -> 0.4
A19: По городам (среди ответивших)
A20: Город | B20: Ответов | C20: Доля
A21: Екатеринбург | B21: =COUNTIFS('Все исполнители'!D:D,A21,'Все исполнители'!J:J,"Прошёл опрос") -> 1 | C21: =B21/SUM($B$21:$B$26) -> 0.1
A22: Казань | B22: =COUNTIFS('Все исполнители'!D:D,A22,'Все исполнители'!J:J,"Прошёл опрос") -> 1 | C22: =B22/SUM($B$21:$B$26) -> 0.1
A23: Краснодар | B23: =COUNTIFS('Все исполнители'!D:D,A23,'Все исполнители'!J:J,"Прошёл опрос") -> 0 | C23: =B23/SUM($B$21:$B$26) -> 0
A24: Москва | B24: =COUNTIFS('Все исполнители'!D:D,A24,'Все исполнители'!J:J,"Прошёл опрос") -> 2 | C24: =B24/SUM($B$21:$B$26) -> 0.2
A25: Новосибирск | B25: =COUNTIFS('Все исполнители'!D:D,A25,'Все исполнители'!J:J,"Прошёл опрос") -> 5 | C25: =B25/SUM($B$21:$B$26) -> 0.5
A26: Санкт-Петербург | B26: =COUNTIFS('Все исполнители'!D:D,A26,'Все исполнители'!J:J,"Прошёл опрос") -> 1 | C26: =B26/SUM($B$21:$B$26) -> 0.1
A28: Файл сгенерирован автоматически из ERP «Рабочие руки». Все формулы пересчитываются при изменении данных.

Sheet Все исполнители
A1: ID | B1: ФИО | C1: Телефон | D1: Город | E1: Категория | F1: Стаж (мес) | G1: Кол-во смен | H1: Увидел сторис | I1: Время просмотра (сек) | J1: Статус | K1: Ответ | L1: Дата/время ответа | M1: Реакция
A2: 10001 | B2: Кузнецов А.А. | C2: +7 941 328-27-23 | D2: Казань | E2: Стройка | F2: 6 | G2: 75 | H2: Да | I2: 0.8 | J2: Прошёл опрос | K2: Другое | L2: 2026-05-05 08:35
A3: 10002 | B3: Богданов А.И. | C3: +7 967 703-45-10 | D3: Санкт-Петербург | E3: Уборка | F3: 22 | G3: 35 | H3: Да | I3: 11.5 | J3: Увидел, не ответил | M3: ❤️
A4: 10003 | B4: Волков Д.М. | C4: +7 987 370-15-68 | D4: Новосибирск | E4: Склад | F4: 25 | G4: 10 | H4: Да | I4: 10 | J4: Увидел, не ответил
A5: 10004 | B5: Воробьёв С.А. | C5: +7 915 777-39-47 | D5: Москва | E5: Курьер | F5: 7 | G5: 48 | H5: Да | I5: 7.8 | J5: Увидел, не ответил
A6: 10005 | B6: Соколов Н.А. | C6: +7 999 799-92-19 | D6: Новосибирск | E6: Курьер | F6: 35 | G6: 93 | H6: Да | I6: 5.8 | J6: Прошёл опрос | K6: Другое | L6: 2026-05-02 18:20
A7: 10006 | B7: Петров С.С. | C7: +7 950 510-44-18 | D7: Санкт-Петербург | E7: Стройка | F7: 21 | G7: 27 | H7: Да | I7: 5 | J7: Увидел, не ответил
A8: 10007 | B8: Козлов М.И. | C8: +7 981 651-43-84 | D8: Екатеринбург | E8: Стройка | F8: 26 | G8: 46 | H8: Да | I8: 12 | J8: Увидел, не ответил | M8: ❤️
A9: 10008 | B9: Кузнецов М.Д. | C9: +7 997 532-86-18 | D9: Екатеринбург | E9: Уборка | F9: 30 | G9: 67 | H9: Да | I9: 6.9 | J9: Увидел, не ответил
A10: 10009 | B10: Кузнецов Н.П. | C10: +7 944 887-92-53 | D10: Москва | E10: Производство | F10: 28 | G10: 20 | H10: Да | I10: 11.5 | J10: Увидел, не ответил
A11: 10010 | B11: Виноградов Р.Д. | C11: +7 974 208-90-48 | D11: Казань | E11: Стройка | F11: 13 | G11: 19 | H11: Да | I11: 2.4 | J11: Увидел, не ответил
A12: 10011 | B12: Иванов М.М. | C12: +7 972 119-24-56 | D12: Краснодар | E12: Курьер | F12: 4 | G12: 30 | H12: Нет | J12: Не увидел
A13: 10012 | B13: Сидоров Д.О. | C13: +7 918 878-78-26 | D13: Санкт-Петербург | E13: Уборка | F13: 36 | G13: 21 | H13: Да | I13: 10.5 | J13: Увидел, не ответил
A14: 10013 | B14: Богданов Р.И. | C14: +7 949 508-95-93 | D14: Краснодар | E14: Уборка | F14: 34 | G14: 57 | H14: Да | I14: 3.1 | J14: Увидел, не ответил
A15: 10014 | B15: Лебедев М.И. | C15: +7 910 172-90-17 | D15: Санкт-Петербург | E15: Склад | F15: 3 | G15: 110 | H15: Да | I15: 6.4 | J15: Прошёл опрос | K15: Telegram-каналы | L15: 2026-05-02 16:08
A16: 10015 | B16: Воробьёв М.О. | C16: +7 941 903-70-62 | D16: Санкт-Петербург | E16: Склад | F16: 7 | G16: 84 | H16: Да | I16: 5.4 | J16: Увидел, не ответил
A17: 10016 | B17: Кузнецов А.В. | C17: +7 953 919-23-41 | D17: Санкт-Петербург | E17: Курьер | F17: 35 | G17: 57 | H17: Да | I17: 2.6 | J17: Увидел, не ответил
A18: 10017 | B18: Сидоров И.П. | C18: +7 922 151-93-79 | D18: Москва | E18: Склад | F18: 16 | G18: 21 | H18: Да | I18: 6 | J18: Увидел, не ответил
A19: 10018 | B19: Попов А.С. | C19: +7 959 371-68-46 | D19: Екатеринбург | E19: Стройка | F19: 32 | G19: 19 | H19: Да | I19: 3 | J19: Прошёл опрос | K19: Другое | L19: 2026-05-01 19:20 | M19: 👍
A20: 10019 | B20: Голубев К.П. | C20: +7 930 158-75-20 | D20: Санкт-Петербург | E20: Склад | F20: 5 | G20: 86 | H20: Нет | J20: Не увидел
A21: 10020 | B21: Алексеев Д.Н. | C21: +7 941 692-86-15 | D21: Новосибирск | E21: Склад | F21: 27 | G21: 84 | H21: Да | I21: 6.5 | J21: Увидел, не ответил
A22: 10021 | B22: Морозов С.А. | C22: +7 960 234-95-92 | D22: Краснодар | E22: Уборка | F22: 21 | G22: 118 | H22: Нет | J22: Не увидел
A23: 10022 | B23: Сидоров А.О. | C23: +7 989 676-22-19 | D23: Новосибирск | E23: Курьер | F23: 33 | G23: 33 | H23: Да | I23: 4.5 | J23: Прошёл опрос | K23: Реклама ВКонтакте | L23: 2026-05-03 12:10
A24: 10023 | B24: Богданов И.А. | C24: +7 988 926-93-77 | D24: Москва | E24: Стройка | F24: 20 | G24: 119 | H24: Да | I24: 11.3 | J24: Прошёл опрос | K24: Через друзей и знакомых | L24: 2026-05-01 19:35 | M24: 🔥
A25: 10024 | B25: Фёдоров С.М. | C25: +7 936 803-91-43 | D25: Новосибирск | E25: Уборка | F25: 17 | G25: 115 | H25: Нет | J25: Не увидел
A26: 10025 | B26: Петров Д.В. | C26: +7 945 145-10-52 | D26: Санкт-Петербург | E26: Производство | F26: 11 | G26: 94 | H26: Да | I26: 8.6 | J26: Увидел, не ответил | M26: 👍
A27: 10026 | B27: Смирнов К.С. | C27: +7 957 696-80-28 | D27: Екатеринбург | E27: Курьер | F27: 3 | G27: 39 | H27: Да | I27: 11.2 | J27: Увидел, не ответил | M27: 🔥
A28: 10027 | B28: Соколов Н.И. | C28: +7 995 205-55-81 | D28: Екатеринбург | E28: Стройка | F28: 10 | G28: 118 | H28: Нет | J28: Не увидел
A29: 10028 | B29: Попов Р.Д. | C29: +7 962 125-32-52 | D29: Екатеринбург | E29: Курьер | F29: 18 | G29: 20 | H29: Нет | J29: Не увидел
A30: 10029 | B30: Кузнецов А.С. | C30: +7 970 327-35-68 | D30: Краснодар | E30: Производство | F30: 15 | G30: 28 | H30: Да | I30: 2.7 | J30: Увидел, не ответил
A31: 10030 | B31: Козлов А.П. | C31: +7 961 795-78-52 | D31: Москва | E31: Склад | F31: 17 | G31: 22 | H31: Да | I31: 11.8 | J31: Прошёл опрос | K31: Другое | L31: 2026-05-04 13:46
A32: 10031 | B32: Лапин М.П. | C32: +7 924 494-83-34 | D32: Краснодар | E32: Склад | F32: 28 | G32: 0 | H32: Да | I32: 9.8 | J32: Увидел, не ответил
A33: 10032 | B33: Соколов А.В. | C33: +7 918 780-52-89 | D33: Краснодар | E33: Склад | F33: 20 | G33: 64 | H33: Да | I33: 5.2 | J33: Увидел, не ответил
A34: 10033 | B34: Смирнов С.В. | C34: +7 995 488-96-32 | D34: Новосибирск | E34: Стройка | F34: 20 | G34: 51 | H34: Да | I34: 0.5 | J34: Прошёл опрос | K34: Telegram-каналы | L34: 2026-05-07 17:38
A35: 10034 | B35: Семёнов И.О. | C35: +7 996 318-75-70 | D35: Казань | E35: Курьер | F35: 6 | G35: 36 | H35: Да | I35: 7.8 | J35: Увидел, не ответил
A36: 10035 | B36: Лебедев Н.А. | C36: +7 938 925-35-28 | D36: Москва | E36: Склад | F36: 16 | G36: 60 | H36: Да | I36: 9.3 | J36: Увидел, не ответил
A37: 10036 | B37: Воробьёв С.В. | C37: +7 973 509-41-28 | D37: Казань | E37: Склад | F37: 7 | G37: 99 | H37: Да | I37: 2.5 | J37: Увидел, не ответил
A38: 10037 | B38: Петров К.И. | C38: +7 925 567-27-69 | D38: Казань | E38: Стройка | F38: 36 | G38: 76 | H38: Да | I38: 9.2 | J38: Увидел, не ответил
A39: 10038 | B39: Виноградов А.П. | C39: +7 967 262-70-67 | D39: Краснодар | E39: Курьер | F39: 18 | G39: 98 | H39: Нет | J39: Не увидел
A40: 10039 | B40: Голубев Н.И. | C40: +7 945 550-19-46 | D40: Санкт-Петербург | E40: Производство | F40: 22 | G40: 40 | H40: Нет | J40: Не увидел
...

Sheet Ответили на опрос
A1: ID | B1: ФИО | C1: Телефон | D1: Город | E1: Категория | F1: Стаж (мес) | G1: Кол-во смен | H1: Увидел сторис | I1: Время просмотра (сек) | J1: Статус | K1: Ответ | L1: Дата/время ответа | M1: Реакция
A2: 10001 | B2: Кузнецов А.А. | C2: +7 941 328-27-23 | D2: Казань | E2: Стройка | F2: 6 | G2: 75 | H2: Да | I2: 0.8 | J2: Прошёл опрос | K2: Другое | L2: 2026-05-05 08:35
A3: 10005 | B3: Соколов Н.А. | C3: +7 999 799-92-19 | D3: Новосибирск | E3: Курьер | F3: 35 | G3: 93 | H3: Да | I3: 5.8 | J3: Прошёл опрос | K3: Другое | L3: 2026-05-02 18:20
A4: 10014 | B4: Лебедев М.И. | C4: +7 910 172-90-17 | D4: Санкт-Петербург | E4: Склад | F4: 3 | G4: 110 | H4: Да | I4: 6.4 | J4: Прошёл опрос | K4: Telegram-каналы | L4: 2026-05-02 16:08
A5: 10018 | B5: Попов А.С. | C5: +7 959 371-68-46 | D5: Екатеринбург | E5: Стройка | F5: 32 | G5: 19 | H5: Да | I5: 3 | J5: Прошёл опрос | K5: Другое | L5: 2026-05-01 19:20 | M5: 👍
A6: 10022 | B6: Сидоров А.О. | C6: +7 989 676-22-19 | D6: Новосибирск | E6: Курьер | F6: 33 | G6: 33 | H6: Да | I6: 4.5 | J6: Прошёл опрос | K6: Реклама ВКонтакте | L6: 2026-05-03 12:10
A7: 10023 | B7: Богданов И.А. | C7: +7 988 926-93-77 | D7: Москва | E7: Стройка | F7: 20 | G7: 119 | H7: Да | I7: 11.3 | J7: Прошёл опрос | K7: Через друзей и знакомых | L7: 2026-05-01 19:35 | M7: 🔥
A8: 10030 | B8: Козлов А.П. | C8: +7 961 795-78-52 | D8: Москва | E8: Склад | F8: 17 | G8: 22 | H8: Да | I8: 11.8 | J8: Прошёл опрос | K8: Другое | L8: 2026-05-04 13:46
A9: 10033 | B9: Смирнов С.В. | C9: +7 995 488-96-32 | D9: Новосибирск | E9: Стройка | F9: 20 | G9: 51 | H9: Да | I9: 0.5 | J9: Прошёл опрос | K9: Telegram-каналы | L9: 2026-05-07 17:38
A10: 10050 | B10: Лебедев Д.А. | C10: +7 945 561-41-69 | D10: Новосибирск | E10: Стройка | F10: 25 | G10: 43 | H10: Да | I10: 10.3 | J10: Прошёл опрос | K10: Реклама ВКонтакте | L10: 2026-05-03 20:16
A11: 10054 | B11: Попов С.И. | C11: +7 971 383-85-77 | D11: Новосибирск | E11: Производство | F11: 7 | G11: 106 | H11: Да | I11: 3.1 | J11: Прошёл опрос | K11: Через друзей и знакомых | L11: 2026-05-06 16:08

Sheet Увидели, не ответили
A1: ⚠ КЛЮЧЕВОЙ СЕГМЕНТ ДЛЯ МАРКЕТИНГА: эти исполнители увидели сторис, но опрос не прошли. Можно использовать для повторной кампании, ретаргетинга, push-уведомления или ручного обзвона.
A3: ID | B3: ФИО | C3: Телефон | D3: Город | E3: Категория | F3: Стаж (мес) | G3: Кол-во смен | H3: Увидел сторис | I3: Время просмотра (сек) | J3: Статус | K3: Ответ | L3: Дата/время ответа | M3: Реакция
A4: 10002 | B4: Богданов А.И. | C4: +7 967 703-45-10 | D4: Санкт-Петербург | E4: Уборка | F4: 22 | G4: 35 | H4: Да | I4: 11.5 | J4: Увидел, не ответил | M4: ❤️
A5: 10003 | B5: Волков Д.М. | C5: +7 987 370-15-68 | D5: Новосибирск | E5: Склад | F5: 25 | G5: 10 | H5: Да | I5: 10 | J5: Увидел, не ответил
A6: 10004 | B6: Воробьёв С.А. | C6: +7 915 777-39-47 | D6: Москва | E6: Курьер | F6: 7 | G6: 48 | H6: Да | I6: 7.8 | J6: Увидел, не ответил
A7: 10006 | B7: Петров С.С. | C7: +7 950 510-44-18 | D7: Санкт-Петербург | E7: Стройка | F7: 21 | G7: 27 | H7: Да | I7: 5 | J7: Увидел, не ответил
A8: 10007 | B8: Козлов М.И. | C8: +7 981 651-43-84 | D8: Екатеринбург | E8: Стройка | F8: 26 | G8: 46 | H8: Да | I8: 12 | J8: Увидел, не ответил | M8: ❤️
A9: 10008 | B9: Кузнецов М.Д. | C9: +7 997 532-86-18 | D9: Екатеринбург | E9: Уборка | F9: 30 | G9: 67 | H9: Да | I9: 6.9 | J9: Увидел, не ответил
A10: 10009 | B10: Кузнецов Н.П. | C10: +7 944 887-92-53 | D10: Москва | E10: Производство | F10: 28 | G10: 20 | H10: Да | I10: 11.5 | J10: Увидел, не ответил
A11: 10010 | B11: Виноградов Р.Д. | C11: +7 974 208-90-48 | D11: Казань | E11: Стройка | F11: 13 | G11: 19 | H11: Да | I11: 2.4 | J11: Увидел, не ответил
A12: 10012 | B12: Сидоров Д.О. | C12: +7 918 878-78-26 | D12: Санкт-Петербург | E12: Уборка | F12: 36 | G12: 21 | H12: Да | I12: 10.5 | J12: Увидел, не ответил
A13: 10013 | B13: Богданов Р.И. | C13: +7 949 508-95-93 | D13: Краснодар | E13: Уборка | F13: 34 | G13: 57 | H13: Да | I13: 3.1 | J13: Увидел, не ответил
A14: 10015 | B14: Воробьёв М.О. | C14: +7 941 903-70-62 | D14: Санкт-Петербург | E14: Склад | F14: 7 | G14: 84 | H14: Да | I14: 5.4 | J14: Увидел, не ответил
A15: 10016 | B15: Кузнецов А.В. | C15: +7 953 919-23-41 | D15: Санкт-Петербург | E15: Курьер | F15: 35 | G15: 57 | H15: Да | I15: 2.6 | J15: Увидел, не ответил
A16: 10017 | B16: Сидоров И.П. | C16: +7 922 151-93-79 | D16: Москва | E16: Склад | F16: 16 | G16: 21 | H16: Да | I16: 6 | J16: Увидел, не ответил
A17: 10020 | B17: Алексеев Д.Н. | C17: +7 941 692-86-15 | D17: Новосибирск | E17: Склад | F17: 27 | G17: 84 | H17: Да | I17: 6.5 | J17: Увидел, не ответил
A18: 10025 | B18: Петров Д.В. | C18: +7 945 145-10-52 | D18: Санкт-Петербург | E18: Производство | F18: 11 | G18: 94 | H18: Да | I18: 8.6 | J18: Увидел, не ответил | M18: 👍
A19: 10026 | B19: Смирнов К.С. | C19: +7 957 696-80-28 | D19: Екатеринбург | E19: Курьер | F19: 3 | G19: 39 | H19: Да | I19: 11.2 | J19: Увидел, не ответил | M19: 🔥
A20: 10029 | B20: Кузнецов А.С. | C20: +7 970 327-35-68 | D20: Краснодар | E20: Производство | F20: 15 | G20: 28 | H20: Да | I20: 2.7 | J20: Увидел, не ответил
A21: 10031 | B21: Лапин М.П. | C21: +7 924 494-83-34 | D21: Краснодар | E21: Склад | F21: 28 | G21: 0 | H21: Да | I21: 9.8 | J21: Увидел, не ответил
A22: 10032 | B22: Соколов А.В. | C22: +7 918 780-52-89 | D22: Краснодар | E22: Склад | F22: 20 | G22: 64 | H22: Да | I22: 5.2 | J22: Увидел, не ответил
A23: 10034 | B23: Семёнов И.О. | C23: +7 996 318-75-70 | D23: Казань | E23: Курьер | F23: 6 | G23: 36 | H23: Да | I23: 7.8 | J23: Увидел, не ответил
A24: 10035 | B24: Лебедев Н.А. | C24: +7 938 925-35-28 | D24: Москва | E24: Склад | F24: 16 | G24: 60 | H24: Да | I24: 9.3 | J24: Увидел, не ответил
A25: 10036 | B25: Воробьёв С.В. | C25: +7 973 509-41-28 | D25: Казань | E25: Склад | F25: 7 | G25: 99 | H25: Да | I25: 2.5 | J25: Увидел, не ответил
A26: 10037 | B26: Петров К.И. | C26: +7 925 567-27-69 | D26: Казань | E26: Стройка | F26: 36 | G26: 76 | H26: Да | I26: 9.2 | J26: Увидел, не ответил
A27: 10040 | B27: Сидоров М.Д. | C27: +7 939 492-98-29 | D27: Казань | E27: Курьер | F27: 5 | G27: 53 | H27: Да | I27: 6.7 | J27: Увидел, не ответил
A28: 10042 | B28: Лапин К.П. | C28: +7 987 325-72-38 | D28: Краснодар | E28: Уборка | F28: 32 | G28: 3 | H28: Да | I28: 8.2 | J28: Увидел, не ответил
A29: 10043 | B29: Семёнов Е.Д. | C29: +7 989 646-13-60 | D29: Новосибирск | E29: Стройка | F29: 2 | G29: 10 | H29: Да | I29: 2.1 | J29: Увидел, не ответил | M29: 🔥
A30: 10044 | B30: Морозов С.О. | C30: +7 951 445-58-45 | D30: Екатеринбург | E30: Производство | F30: 6 | G30: 60 | H30: Да | I30: 6.7 | J30: Увидел, не ответил
A31: 10045 | B31: Сидоров Р.С. | C31: +7 913 353-35-12 | D31: Новосибирск | E31: Курьер | F31: 16 | G31: 16 | H31: Да | I31: 1.8 | J31: Увидел, не ответил
A32: 10046 | B32: Козлов Р.М. | C32: +7 931 720-87-24 | D32: Санкт-Петербург | E32: Производство | F32: 7 | G32: 74 | H32: Да | I32: 4.1 | J32: Увидел, не ответил
A33: 10047 | B33: Алексеев И.И. | C33: +7 919 706-98-90 | D33: Санкт-Петербург | E33: Склад | F33: 20 | G33: 108 | H33: Да | I33: 9.8 | J33: Увидел, не ответил
A34: 10048 | B34: Петров А.П. | C34: +7 964 777-57-18 | D34: Новосибирск | E34: Производство | F34: 1 | G34: 108 | H34: Да | I34: 6.1 | J34: Увидел, не ответил
A35: 10049 | B35: Семёнов И.Д. | C35: +7 965 280-76-93 | D35: Краснодар | E35: Стройка | F35: 35 | G35: 99 | H35: Да | I35: 5.5 | J35: Увидел, не ответил
A36: 10051 | B36: Фёдоров И.А. | C36: +7 981 110-76-34 | D36: Москва | E36: Курьер | F36: 27 | G36: 62 | H36: Да | I36: 3.3 | J36: Увидел, не ответил
A37: 10052 | B37: Семёнов Р.С. | C37: +7 921 401-38-61 | D37: Казань | E37: Курьер | F37: 20 | G37: 84 | H37: Да | I37: 5.9 | J37: Увидел, не ответил
A38: 10053 | B38: Богданов А.М. | C38: +7 999 564-44-49 | D38: Краснодар | E38: Курьер | F38: 8 | G38: 92 | H38: Да | I38: 1.9 | J38: Увидел, не ответил
A39: 10055 | B39: Петров К.А. | C39: +7 999 229-91-72 | D39: Москва | E39: Склад | F39: 19 | G39: 60 | H39: Да | I39: 4.4 | J39: Увидел, не ответил
A40: 10057 | B40: Новиков Д.И. | C40: +7 925 671-63-87 | D40: Новосибирск | E40: Стройка | F40: 15 | G40: 99 | H40: Да | I40: 5.7 | J40: Увидел, не ответил
A41: 10058 | B41: Лапин А.Н. | C41: +7 989 161-88-22 | D41: Санкт-Петербург | E41: Курьер | F41: 17 | G41: 84 | H41: Да | I41: 3.3 | J41: Увидел, не ответил | M41: 🔥
...

Sheet Не увидели сторис
A1: ID | B1: ФИО | C1: Телефон | D1: Город | E1: Категория | F1: Стаж (мес) | G1: Кол-во смен | H1: Увидел сторис | I1: Время просмотра (сек) | J1: Статус | K1: Ответ | L1: Дата/время ответа | M1: Реакция
A2: 10011 | B2: Иванов М.М. | C2: +7 972 119-24-56 | D2: Краснодар | E2: Курьер | F2: 4 | G2: 30 | H2: Нет | J2: Не увидел
A3: 10019 | B3: Голубев К.П. | C3: +7 930 158-75-20 | D3: Санкт-Петербург | E3: Склад | F3: 5 | G3: 86 | H3: Нет | J3: Не увидел
A4: 10021 | B4: Морозов С.А. | C4: +7 960 234-95-92 | D4: Краснодар | E4: Уборка | F4: 21 | G4: 118 | H4: Нет | J4: Не увидел
A5: 10024 | B5: Фёдоров С.М. | C5: +7 936 803-91-43 | D5: Новосибирск | E5: Уборка | F5: 17 | G5: 115 | H5: Нет | J5: Не увидел
A6: 10027 | B6: Соколов Н.И. | C6: +7 995 205-55-81 | D6: Екатеринбург | E6: Стройка | F6: 10 | G6: 118 | H6: Нет | J6: Не увидел
A7: 10028 | B7: Попов Р.Д. | C7: +7 962 125-32-52 | D7: Екатеринбург | E7: Курьер | F7: 18 | G7: 20 | H7: Нет | J7: Не увидел
A8: 10038 | B8: Виноградов А.П. | C8: +7 967 262-70-67 | D8: Краснодар | E8: Курьер | F8: 18 | G8: 98 | H8: Нет | J8: Не увидел
A9: 10039 | B9: Голубев Н.И. | C9: +7 945 550-19-46 | D9: Санкт-Петербург | E9: Производство | F9: 22 | G9: 40 | H9: Нет | J9: Не увидел
A10: 10041 | B10: Лапин А.Н. | C10: +7 999 120-83-58 | D10: Екатеринбург | E10: Склад | F10: 23 | G10: 38 | H10: Нет | J10: Не увидел
A11: 10056 | B11: Голубев Д.А. | C11: +7 961 603-19-83 | D11: Казань | E11: Склад | F11: 10 | G11: 19 | H11: Нет | J11: Не увидел
